..EE.F.EE..
======================================================================
ERROR: test_login (tests.test_auth.TestAuth.test_login)
----------------------------------------------------------------------
Traceback (most recent call last):
  File "/home/runner/workspace/tests/test_auth.py", line 12, in setUp
    db.create_all()
  File "/home/runner/workspace/.pythonlibs/lib/python3.12/site-packages/flask_sqlalchemy/extension.py", line 900, in create_all
    self._call_for_binds(bind_key, "create_all")
  File "/home/runner/workspace/.pythonlibs/lib/python3.12/site-packages/flask_sqlalchemy/extension.py", line 871, in _call_for_binds
    engine = self.engines[key]
             ^^^^^^^^^^^^
  File "/home/runner/workspace/.pythonlibs/lib/python3.12/site-packages/flask_sqlalchemy/extension.py", line 690, in engines
    raise RuntimeError(
RuntimeError: The current Flask app is not registered with this 'SQLAlchemy' instance. Did you forget to call 'init_app', or did you create multiple 'SQLAlchemy' instances?

======================================================================
ERROR: test_register (tests.test_auth.TestAuth.test_register)
----------------------------------------------------------------------
Traceback (most recent call last):
  File "/home/runner/workspace/tests/test_auth.py", line 12, in setUp
    db.create_all()
  File "/home/runner/workspace/.pythonlibs/lib/python3.12/site-packages/flask_sqlalchemy/extension.py", line 900, in create_all
    self._call_for_binds(bind_key, "create_all")
  File "/home/runner/workspace/.pythonlibs/lib/python3.12/site-packages/flask_sqlalchemy/extension.py", line 871, in _call_for_binds
    engine = self.engines[key]
             ^^^^^^^^^^^^
  File "/home/runner/workspace/.pythonlibs/lib/python3.12/site-packages/flask_sqlalchemy/extension.py", line 690, in engines
    raise RuntimeError(
RuntimeError: The current Flask app is not registered with this 'SQLAlchemy' instance. Did you forget to call 'init_app', or did you create multiple 'SQLAlchemy' instances?

======================================================================
ERROR: test_add_university (tests.test_university_portal.TestUniversityPortal.test_add_university)
----------------------------------------------------------------------
Traceback (most recent call last):
  File "/home/runner/workspace/tests/test_university_portal.py", line 12, in setUp
    db.init_app(app)
  File "/home/runner/workspace/.pythonlibs/lib/python3.12/site-packages/flask_sqlalchemy/extension.py", line 312, in init_app
    raise RuntimeError(
RuntimeError: A 'SQLAlchemy' instance has already been registered on this Flask app. Import and use that instance instead.

======================================================================
ERROR: test_update_requirements (tests.test_university_portal.TestUniversityPortal.test_update_requirements)
----------------------------------------------------------------------
Traceback (most recent call last):
  File "/home/runner/workspace/tests/test_university_portal.py", line 12, in setUp
    db.init_app(app)
  File "/home/runner/workspace/.pythonlibs/lib/python3.12/site-packages/flask_sqlalchemy/extension.py", line 312, in init_app
    raise RuntimeError(
RuntimeError: A 'SQLAlchemy' instance has already been registered on this Flask app. Import and use that instance instead.

======================================================================
FAIL: test_submit_consent (tests.test_gdpr.TestGDPR.test_submit_consent)
----------------------------------------------------------------------
Traceback (most recent call last):
  File "/home/runner/workspace/tests/test_gdpr.py", line 24, in test_submit_consent
    self.assertEqual(response.status_code, 302)
AssertionError: 404 != 302

----------------------------------------------------------------------
Ran 11 tests in 0.027s

FAILED (failures=1, errors=4)